Workbook
Name SegmentaciónDeDatos_C_Edad: #N/A
Name SegmentaciónDeDatos_Clase: #N/A
Name SegmentaciónDeDatos_Sexo: #N/A

Sheet Tipos de análisis
B3: Análisis en Grupos de Datos | E3: Todo es una categoría y se observa un valor resumido
F4: Valor agregado: Suma, Promedio, Recuento, Mínimo, Máximo, …
C6: Conteos de grupos que se transforman en probabilidades
B9: Análisis de Tendencia de Datos | E9: Todo es una tendencia y ser observa un valor continuo
F10: Series de datos: Lineales/Indexados, Temporales/Periódicos
C12: Acumulaciones, Diferencias y Regresiones que se transforman en tendencias

Sheet Titanic
G2: {=SUM((Titanic[Edad]="")*1)} -> 177
B5: Indice | C5: Sobrevive | D5: Clase | E5: Nombre | F5: Sexo | G5: Edad | H5: Familia Horizontal | I5: Familia Vertical | J5: Pagado | K5: Cabina | L5: Puerto | M5: C Sobrevive | N5: C Clase | O5: C Sexo | P5: Edad Corrigida | Q5: C Edad | R5: Familiares | S5: C Familiares | T5: C Pago | U5: C Cabina | V5: C Puerto
B6: 1 | C6: 0 | D6: 3 | E6: Braund, Mr. Owen Harris | F6: Hombre | G6: 22 | H6: 1 | I6: 0 | J6: 725 | K6: 0 | L6: Southampton | M6: =IF(Titanic[[#This Row],[Sobrevive]]=1, "SOBREVIVE", "NO SOBREVIVE") -> NO SOBREVIVE | N6: =LOOKUP(Titanic[[#This Row],[Clase]],{1,2,3}, {"PRIMERA","SEGUNDA","TERCERA"}) -> TERCERA | O6: =IF(Titanic[[#This Row],[Sexo]]="Hombre", "HOMBRE", "MUJER") -> HOMBRE | P6: =IF(Titanic[[#This Row],[Edad]]="", "", IF(Titanic[[#This Row],[Edad]]>=100, Titanic[[#This Row],[Edad]] / 10, Titanic[[#This Row],[Edad]])) -> 22 | Q6: =IFERROR(LOOKUP(Titanic[[#This Row],[Edad Corrigida]],'Práctica 1'!$K$231:$K$240,'Práctica 1'!$L$231:$L$240), "DESCONOCIDO") -> 3. JOVEN | R6: =Titanic[[#This Row],[Familia Horizontal]]+Titanic[[#This Row],[Familia Vertical]] -> 1
B7: 2 | C7: 1 | D7: 1 | E7: Cumings, Mrs. John Bradley (Florence Briggs Thayer) | F7: Mujer | G7: 38 | H7: 1 | I7: 0 | J7: 712833 | K7: 1 | L7: Cherburg | M7: =IF(Titanic[[#This Row],[Sobrevive]]=1, "SOBREVIVE", "NO SOBREVIVE") -> SOBREVIVE | N7: =LOOKUP(Titanic[[#This Row],[Clase]],{1,2,3}, {"PRIMERA","SEGUNDA","TERCERA"}) -> PRIMERA | O7: =IF(Titanic[[#This Row],[Sexo]]="Hombre", "HOMBRE", "MUJER") -> MUJER | P7: =IF(Titanic[[#This Row],[Edad]]="", "", IF(Titanic[[#This Row],[Edad]]>=100, Titanic[[#This Row],[Edad]] / 10, Titanic[[#This Row],[Edad]])) -> 38 | Q7: =IFERROR(LOOKUP(Titanic[[#This Row],[Edad Corrigida]],'Práctica 1'!$K$231:$K$240,'Práctica 1'!$L$231:$L$240), "DESCONOCIDO") -> 7. ADULTO 2 | R7: =Titanic[[#This Row],[Familia Horizontal]]+Titanic[[#This Row],[Familia Vertical]] -> 1
B8: 3 | C8: 1 | D8: 3 | E8: Heikkinen, Miss. Laina | F8: Mujer | G8: 26 | H8: 0 | I8: 0 | J8: 7925 | K8: 0 | L8: Southampton | M8: =IF(Titanic[[#This Row],[Sobrevive]]=1, "SOBREVIVE", "NO SOBREVIVE") -> SOBREVIVE | N8: =LOOKUP(Titanic[[#This Row],[Clase]],{1,2,3}, {"PRIMERA","SEGUNDA","TERCERA"}) -> TERCERA | O8: =IF(Titanic[[#This Row],[Sexo]]="Hombre", "HOMBRE", "MUJER") -> MUJER | P8: =IF(Titanic[[#This Row],[Edad]]="", "", IF(Titanic[[#This Row],[Edad]]>=100, Titanic[[#This Row],[Edad]] / 10, Titanic[[#This Row],[Edad]])) -> 26 | Q8: =IFERROR(LOOKUP(Titanic[[#This Row],[Edad Corrigida]],'Práctica 1'!$K$231:$K$240,'Práctica 1'!$L$231:$L$240), "DESCONOCIDO") -> 4. ADULTO JOVEN | R8: =Titanic[[#This Row],[Familia Horizontal]]+Titanic[[#This Row],[Familia Vertical]] -> 0
B9: 4 | C9: 1 | D9: 1 | E9: Futrelle, Mrs. Jacques Heath (Lily May Peel) | F9: Mujer | G9: 35 | H9: 1 | I9: 0 | J9: 531 | K9: 1 | L9: Southampton | M9: =IF(Titanic[[#This Row],[Sobrevive]]=1, "SOBREVIVE", "NO SOBREVIVE") -> SOBREVIVE | N9: =LOOKUP(Titanic[[#This Row],[Clase]],{1,2,3}, {"PRIMERA","SEGUNDA","TERCERA"}) -> PRIMERA | O9: =IF(Titanic[[#This Row],[Sexo]]="Hombre", "HOMBRE", "MUJER") -> MUJER | P9: =IF(Titanic[[#This Row],[Edad]]="", "", IF(Titanic[[#This Row],[Edad]]>=100, Titanic[[#This Row],[Edad]] / 10, Titanic[[#This Row],[Edad]])) -> 35 | Q9: =IFERROR(LOOKUP(Titanic[[#This Row],[Edad Corrigida]],'Práctica 1'!$K$231:$K$240,'Práctica 1'!$L$231:$L$240), "DESCONOCIDO") -> 6. ADULTO 1 | R9: =Titanic[[#This Row],[Familia Horizontal]]+Titanic[[#This Row],[Familia Vertical]] -> 1
B10: 5 | C10: 0 | D10: 3 | E10: Allen, Mr. William Henry | F10: Hombre | G10: 35 | H10: 0 | I10: 0 | J10: 805 | K10: 0 | L10: Southampton | M10: =IF(Titanic[[#This Row],[Sobrevive]]=1, "SOBREVIVE", "NO SOBREVIVE") -> NO SOBREVIVE | N10: =LOOKUP(Titanic[[#This Row],[Clase]],{1,2,3}, {"PRIMERA","SEGUNDA","TERCERA"}) -> TERCERA | O10: =IF(Titanic[[#This Row],[Sexo]]="Hombre", "HOMBRE", "MUJER") -> HOMBRE | P10: =IF(Titanic[[#This Row],[Edad]]="", "", IF(Titanic[[#This Row],[Edad]]>=100, Titanic[[#This Row],[Edad]] / 10, Titanic[[#This Row],[Edad]])) -> 35 | Q10: =IFERROR(LOOKUP(Titanic[[#This Row],[Edad Corrigida]],'Práctica 1'!$K$231:$K$240,'Práctica 1'!$L$231:$L$240), "DESCONOCIDO") -> 6. ADULTO 1 | R10: =Titanic[[#This Row],[Familia Horizontal]]+Titanic[[#This Row],[Familia Vertical]] -> 0
B11: 6 | C11: 0 | D11: 3 | E11: Moran, Mr. James | F11: Hombre | H11: 0 | I11: 0 | J11: 84583 | K11: 0 | L11: Queenstown | M11: =IF(Titanic[[#This Row],[Sobrevive]]=1, "SOBREVIVE", "NO SOBREVIVE") -> NO SOBREVIVE | N11: =LOOKUP(Titanic[[#This Row],[Clase]],{1,2,3}, {"PRIMERA","SEGUNDA","TERCERA"}) -> TERCERA | O11: =IF(Titanic[[#This Row],[Sexo]]="Hombre", "HOMBRE", "MUJER") -> HOMBRE | P11: =IF(Titanic[[#This Row],[Edad]]="", "", IF(Titanic[[#This Row],[Edad]]>=100, Titanic[[#This Row],[Edad]] / 10, Titanic[[#This Row],[Edad]])) | Q11: =IFERROR(LOOKUP(Titanic[[#This Row],[Edad Corrigida]],'Práctica 1'!$K$231:$K$240,'Práctica 1'!$L$231:$L$240), "DESCONOCIDO") -> DESCONOCIDO | R11: =Titanic[[#This Row],[Familia Horizontal]]+Titanic[[#This Row],[Familia Vertical]] -> 0
B12: 7 | C12: 0 | D12: 1 | E12: McCarthy, Mr. Timothy J | F12: Hombre | G12: 54 | H12: 0 | I12: 0 | J12: 518625 | K12: 1 | L12: Southampton | M12: =IF(Titanic[[#This Row],[Sobrevive]]=1, "SOBREVIVE", "NO SOBREVIVE") -> NO SOBREVIVE | N12: =LOOKUP(Titanic[[#This Row],[Clase]],{1,2,3}, {"PRIMERA","SEGUNDA","TERCERA"}) -> PRIMERA | O12: =IF(Titanic[[#This Row],[Sexo]]="Hombre", "HOMBRE", "MUJER") -> HOMBRE | P12: =IF(Titanic[[#This Row],[Edad]]="", "", IF(Titanic[[#This Row],[Edad]]>=100, Titanic[[#This Row],[Edad]] / 10, Titanic[[#This Row],[Edad]])) -> 54 | Q12: =IFERROR(LOOKUP(Titanic[[#This Row],[Edad Corrigida]],'Práctica 1'!$K$231:$K$240,'Práctica 1'!$L$231:$L$240), "DESCONOCIDO") -> 9. ADULTO 4 | R12: =Titanic[[#This Row],[Familia Horizontal]]+Titanic[[#This Row],[Familia Vertical]] -> 0
B13: 8 | C13: 0 | D13: 3 | E13: Palsson, Master. Gosta Leonard | F13: Hombre | G13: 2 | H13: 3 | I13: 1 | J13: 21075 | K13: 0 | L13: Southampton | M13: =IF(Titanic[[#This Row],[Sobrevive]]=1, "SOBREVIVE", "NO SOBREVIVE") -> NO SOBREVIVE | N13: =LOOKUP(Titanic[[#This Row],[Clase]],{1,2,3}, {"PRIMERA","SEGUNDA","TERCERA"}) -> TERCERA | O13: =IF(Titanic[[#This Row],[Sexo]]="Hombre", "HOMBRE", "MUJER") -> HOMBRE | P13: =IF(Titanic[[#This Row],[Edad]]="", "", IF(Titanic[[#This Row],[Edad]]>=100, Titanic[[#This Row],[Edad]] / 10, Titanic[[#This Row],[Edad]])) -> 2 | Q13: =IFERROR(LOOKUP(Titanic[[#This Row],[Edad Corrigida]],'Práctica 1'!$K$231:$K$240,'Práctica 1'!$L$231:$L$240), "DESCONOCIDO") -> DESCONOCIDO | R13: =Titanic[[#This Row],[Familia Horizontal]]+Titanic[[#This Row],[Familia Vertical]] -> 4
B14: 9 | C14: 1 | D14: 3 | E14: Johnson, Mrs. Oscar W (Elisabeth Vilhelmina Berg) | F14: Mujer | G14: 27 | H14: 0 | I14: 2 | J14: 111333 | K14: 0 | L14: Southampton | M14: =IF(Titanic[[#This Row],[Sobrevive]]=1, "SOBREVIVE", "NO SOBREVIVE") -> SOBREVIVE | N14: =LOOKUP(Titanic[[#This Row],[Clase]],{1,2,3}, {"PRIMERA","SEGUNDA","TERCERA"}) -> TERCERA | O14: =IF(Titanic[[#This Row],[Sexo]]="Hombre", "HOMBRE", "MUJER") -> MUJER | P14: =IF(Titanic[[#This Row],[Edad]]="", "", IF(Titanic[[#This Row],[Edad]]>=100, Titanic[[#This Row],[Edad]] / 10, Titanic[[#This Row],[Edad]])) -> 27 | Q14: =IFERROR(LOOKUP(Titanic[[#This Row],[Edad Corrigida]],'Práctica 1'!$K$231:$K$240,'Práctica 1'!$L$231:$L$240), "DESCONOCIDO") -> 4. ADULTO JOVEN | R14: =Titanic[[#This Row],[Familia Horizontal]]+Titanic[[#This Row],[Familia Vertical]] -> 2
B15: 10 | C15: 1 | D15: 2 | E15: Nasser, Mrs. Nicholas (Adele Achem) | F15: Mujer | G15: 14 | H15: 1 | I15: 0 | J15: 300708 | K15: 0 | L15: Cherburg | M15: =IF(Titanic[[#This Row],[Sobrevive]]=1, "SOBREVIVE", "NO SOBREVIVE") -> SOBREVIVE | N15: =LOOKUP(Titanic[[#This Row],[Clase]],{1,2,3}, {"PRIMERA","SEGUNDA","TERCERA"}) -> SEGUNDA | O15: =IF(Titanic[[#This Row],[Sexo]]="Hombre", "HOMBRE", "MUJER") -> MUJER | P15: =IF(Titanic[[#This Row],[Edad]]="", "", IF(Titanic[[#This Row],[Edad]]>=100, Titanic[[#This Row],[Edad]] / 10, Titanic[[#This Row],[Edad]])) -> 14 | Q15: =IFERROR(LOOKUP(Titanic[[#This Row],[Edad Corrigida]],'Práctica 1'!$K$231:$K$240,'Práctica 1'!$L$231:$L$240), "DESCONOCIDO") -> DESCONOCIDO | R15: =Titanic[[#This Row],[Familia Horizontal]]+Titanic[[#This Row],[Familia Vertical]] -> 1
B16: 11 | C16: 1 | D16: 3 | E16: Sandstrom, Miss. Marguerite Rut | F16: Mujer | G16: 4 | H16: 1 | I16: 1 | J16: 167 | K16: 1 | L16: Southampton | M16: =IF(Titanic[[#This Row],[Sobrevive]]=1, "SOBREVIVE", "NO SOBREVIVE") -> SOBREVIVE | N16: =LOOKUP(Titanic[[#This Row],[Clase]],{1,2,3}, {"PRIMERA","SEGUNDA","TERCERA"}) -> TERCERA | O16: =IF(Titanic[[#This Row],[Sexo]]="Hombre", "HOMBRE", "MUJER") -> MUJER | P16: =IF(Titanic[[#This Row],[Edad]]="", "", IF(Titanic[[#This Row],[Edad]]>=100, Titanic[[#This Row],[Edad]] / 10, Titanic[[#This Row],[Edad]])) -> 4 | Q16: =IFERROR(LOOKUP(Titanic[[#This Row],[Edad Corrigida]],'Práctica 1'!$K$231:$K$240,'Práctica 1'!$L$231:$L$240), "DESCONOCIDO") -> DESCONOCIDO | R16: =Titanic[[#This Row],[Familia Horizontal]]+Titanic[[#This Row],[Familia Vertical]] -> 2
B17: 12 | C17: 1 | D17: 1 | E17: Bonnell, Miss. Elizabeth | F17: Mujer | G17: 58 | H17: 0 | I17: 0 | J17: 2655 | K17: 1 | L17: Southampton | M17: =IF(Titanic[[#This Row],[Sobrevive]]=1, "SOBREVIVE", "NO SOBREVIVE") -> SOBREVIVE | N17: =LOOKUP(Titanic[[#This Row],[Clase]],{1,2,3}, {"PRIMERA","SEGUNDA","TERCERA"}) -> PRIMERA | O17: =IF(Titanic[[#This Row],[Sexo]]="Hombre", "HOMBRE", "MUJER") -> MUJER | P17: =IF(Titanic[[#This Row],[Edad]]="", "", IF(Titanic[[#This Row],[Edad]]>=100, Titanic[[#This Row],[Edad]] / 10, Titanic[[#This Row],[Edad]])) -> 58 | Q17: =IFERROR(LOOKUP(Titanic[[#This Row],[Edad Corrigida]],'Práctica 1'!$K$231:$K$240,'Práctica 1'!$L$231:$L$240), "DESCONOCIDO") -> 9. ADULTO 4 | R17: =Titanic[[#This Row],[Familia Horizontal]]+Titanic[[#This Row],[Familia Vertical]] -> 0
B18: 13 | C18: 0 | D18: 3 | E18: Saundercock, Mr. William Henry | F18: Hombre | G18: 20 | H18: 0 | I18: 0 | J18: 805 | K18: 0 | L18: Southampton | M18: =IF(Titanic[[#This Row],[Sobrevive]]=1, "SOBREVIVE", "NO SOBREVIVE") -> NO SOBREVIVE | N18: =LOOKUP(Titanic[[#This Row],[Clase]],{1,2,3}, {"PRIMERA","SEGUNDA","TERCERA"}) -> TERCERA | O18: =IF(Titanic[[#This Row],[Sexo]]="Hombre", "HOMBRE", "MUJER") -> HOMBRE | P18: =IF(Titanic[[#This Row],[Edad]]="", "", IF(Titanic[[#This Row],[Edad]]>=100, Titanic[[#This Row],[Edad]] / 10, Titanic[[#This Row],[Edad]])) -> 20 | Q18: =IFERROR(LOOKUP(Titanic[[#This Row],[Edad Corrigida]],'Práctica 1'!$K$231:$K$240,'Práctica 1'!$L$231:$L$240), "DESCONOCIDO") -> 2. ADOLESCENTE | R18: =Titanic[[#This Row],[Familia Horizontal]]+Titanic[[#This Row],[Familia Vertical]] -> 0
B19: 14 | C19: 0 | D19: 3 | E19: Andersson, Mr. Anders Johan | F19: Hombre | G19: 39 | H19: 1 | I19: 5 | J19: 31275 | K19: 0 | L19: Southampton | M19: =IF(Titanic[[#This Row],[Sobrevive]]=1, "SOBREVIVE", "NO SOBREVIVE") -> NO SOBREVIVE | N19: =LOOKUP(Titanic[[#This Row],[Clase]],{1,2,3}, {"PRIMERA","SEGUNDA","TERCERA"}) -> TERCERA | O19: =IF(Titanic[[#This Row],[Sexo]]="Hombre", "HOMBRE", "MUJER") -> HOMBRE | P19: =IF(Titanic[[#This Row],[Edad]]="", "", IF(Titanic[[#This Row],[Edad]]>=100, Titanic[[#This Row],[Edad]] / 10, Titanic[[#This Row],[Edad]])) -> 39 | Q19: =IFERROR(LOOKUP(Titanic[[#This Row],[Edad Corrigida]],'Práctica 1'!$K$231:$K$240,'Práctica 1'!$L$231:$L$240), "DESCONOCIDO") -> 7. ADULTO 2 | R19: =Titanic[[#This Row],[Familia Horizontal]]+Titanic[[#This Row],[Familia Vertical]] -> 6
B20: 15 | C20: 0 | D20: 3 | E20: Vestrom, Miss. Hulda Amanda Adolfina | F20: Mujer | G20: 14 | H20: 0 | I20: 0 | J20: 78542 | K20: 0 | L20: Southampton | M20: =IF(Titanic[[#This Row],[Sobrevive]]=1, "SOBREVIVE", "NO SOBREVIVE") -> NO SOBREVIVE | N20: =LOOKUP(Titanic[[#This Row],[Clase]],{1,2,3}, {"PRIMERA","SEGUNDA","TERCERA"}) -> TERCERA | O20: =IF(Titanic[[#This Row],[Sexo]]="Hombre", "HOMBRE", "MUJER") -> MUJER | P20: =IF(Titanic[[#This Row],[Edad]]="", "", IF(Titanic[[#This Row],[Edad]]>=100, Titanic[[#This Row],[Edad]] / 10, Titanic[[#This Row],[Edad]])) -> 14 | Q20: =IFERROR(LOOKUP(Titanic[[#This Row],[Edad Corrigida]],'Práctica 1'!$K$231:$K$240,'Práctica 1'!$L$231:$L$240), "DESCONOCIDO") -> DESCONOCIDO | R20: =Titanic[[#This Row],[Familia Horizontal]]+Titanic[[#This Row],[Familia Vertical]] -> 0
B21: 16 | C21: 1 | D21: 2 | E21: Hewlett, Mrs. (Mary D Kingcome) | F21: Mujer | G21: 55 | H21: 0 | I21: 0 | J21: 16 | K21: 0 | L21: Southampton | M21: =IF(Titanic[[#This Row],[Sobrevive]]=1, "SOBREVIVE", "NO SOBREVIVE") -> SOBREVIVE | N21: =LOOKUP(Titanic[[#This Row],[Clase]],{1,2,3}, {"PRIMERA","SEGUNDA","TERCERA"}) -> SEGUNDA | O21: =IF(Titanic[[#This Row],[Sexo]]="Hombre", "HOMBRE", "MUJER") -> MUJER | P21: =IF(Titanic[[#This Row],[Edad]]="", "", IF(Titanic[[#This Row],[Edad]]>=100, Titanic[[#This Row],[Edad]] / 10, Titanic[[#This Row],[Edad]])) -> 55 | Q21: =IFERROR(LOOKUP(Titanic[[#This Row],[Edad Corrigida]],'Práctica 1'!$K$231:$K$240,'Práctica 1'!$L$231:$L$240), "DESCONOCIDO") -> 9. ADULTO 4 | R21: =Titanic[[#This Row],[Familia Horizontal]]+Titanic[[#This Row],[Familia Vertical]] -> 0
B22: 17 | C22: 0 | D22: 3 | E22: Rice, Master. Eugene | F22: Hombre | G22: 2 | H22: 4 | I22: 1 | J22: 29125 | K22: 0 | L22: Queenstown | M22: =IF(Titanic[[#This Row],[Sobrevive]]=1, "SOBREVIVE", "NO SOBREVIVE") -> NO SOBREVIVE | N22: =LOOKUP(Titanic[[#This Row],[Clase]],{1,2,3}, {"PRIMERA","SEGUNDA","TERCERA"}) -> TERCERA | O22: =IF(Titanic[[#This Row],[Sexo]]="Hombre", "HOMBRE", "MUJER") -> HOMBRE | P22: =IF(Titanic[[#This Row],[Edad]]="", "", IF(Titanic[[#This Row],[Edad]]>=100, Titanic[[#This Row],[Edad]] / 10, Titanic[[#This Row],[Edad]])) -> 2 | Q22: =IFERROR(LOOKUP(Titanic[[#This Row],[Edad Corrigida]],'Práctica 1'!$K$231:$K$240,'Práctica 1'!$L$231:$L$240), "DESCONOCIDO") -> DESCONOCIDO | R22: =Titanic[[#This Row],[Familia Horizontal]]+Titanic[[#This Row],[Familia Vertical]] -> 5
B23: 18 | C23: 1 | D23: 2 | E23: Williams, Mr. Charles Eugene | F23: Hombre | H23: 0 | I23: 0 | J23: 13 | K23: 0 | L23: Southampton | M23: =IF(Titanic[[#This Row],[Sobrevive]]=1, "SOBREVIVE", "NO SOBREVIVE") -> SOBREVIVE | N23: =LOOKUP(Titanic[[#This Row],[Clase]],{1,2,3}, {"PRIMERA","SEGUNDA","TERCERA"}) -> SEGUNDA | O23: =IF(Titanic[[#This Row],[Sexo]]="Hombre", "HOMBRE", "MUJER") -> HOMBRE | P23: =IF(Titanic[[#This Row],[Edad]]="", "", IF(Titanic[[#This Row],[Edad]]>=100, Titanic[[#This Row],[Edad]] / 10, Titanic[[#This Row],[Edad]])) | Q23: =IFERROR(LOOKUP(Titanic[[#This Row],[Edad Corrigida]],'Práctica 1'!$K$231:$K$240,'Práctica 1'!$L$231:$L$240), "DESCONOCIDO") -> DESCONOCIDO | R23: =Titanic[[#This Row],[Familia Horizontal]]+Titanic[[#This Row],[Familia Vertical]] -> 0
B24: 19 | C24: 0 | D24: 3 | E24: Vander Planke, Mrs. Julius (Emelia Maria Vandemoortele) | F24: Mujer | G24: 31 | H24: 1 | I24: 0 | J24: 18 | K24: 0 | L24: Southampton | M24: =IF(Titanic[[#This Row],[Sobrevive]]=1, "SOBREVIVE", "NO SOBREVIVE") -> NO SOBREVIVE | N24: =LOOKUP(Titanic[[#This Row],[Clase]],{1,2,3}, {"PRIMERA","SEGUNDA","TERCERA"}) -> TERCERA | O24: =IF(Titanic[[#This Row],[Sexo]]="Hombre", "HOMBRE", "MUJER") -> MUJER | P24: =IF(Titanic[[#This Row],[Edad]]="", "", IF(Titanic[[#This Row],[Edad]]>=100, Titanic[[#This Row],[Edad]] / 10, Titanic[[#This Row],[Edad]])) -> 31 | Q24: =IFERROR(LOOKUP(Titanic[[#This Row],[Edad Corrigida]],'Práctica 1'!$K$231:$K$240,'Práctica 1'!$L$231:$L$240), "DESCONOCIDO") -> 5. ADULTO | R24: =Titanic[[#This Row],[Familia Horizontal]]+Titanic[[#This Row],[Familia Vertical]] -> 1
B25: 20 | C25: 1 | D25: 3 | E25: Masselmani, Mrs. Fatima | F25: Mujer | H25: 0 | I25: 0 | J25: 7225 | K25: 0 | L25: Cherburg | M25: =IF(Titanic[[#This Row],[Sobrevive]]=1, "SOBREVIVE", "NO SOBREVIVE") -> SOBREVIVE | N25: =LOOKUP(Titanic[[#This Row],[Clase]],{1,2,3}, {"PRIMERA","SEGUNDA","TERCERA"}) -> TERCERA | O25: =IF(Titanic[[#This Row],[Sexo]]="Hombre", "HOMBRE", "MUJER") -> MUJER | P25: =IF(Titanic[[#This Row],[Edad]]="", "", IF(Titanic[[#This Row],[Edad]]>=100, Titanic[[#This Row],[Edad]] / 10, Titanic[[#This Row],[Edad]])) | Q25: =IFERROR(LOOKUP(Titanic[[#This Row],[Edad Corrigida]],'Práctica 1'!$K$231:$K$240,'Práctica 1'!$L$231:$L$240), "DESCONOCIDO") -> DESCONOCIDO | R25: =Titanic[[#This Row],[Familia Horizontal]]+Titanic[[#This Row],[Familia Vertical]] -> 0
B26: 21 | C26: 0 | D26: 2 | E26: Fynney, Mr. Joseph J | F26: Hombre | G26: 35 | H26: 0 | I26: 0 | J26: 26 | K26: 0 | L26: Southampton | M26: =IF(Titanic[[#This Row],[Sobrevive]]=1, "SOBREVIVE", "NO SOBREVIVE") -> NO SOBREVIVE | N26: =LOOKUP(Titanic[[#This Row],[Clase]],{1,2,3}, {"PRIMERA","SEGUNDA","TERCERA"}) -> SEGUNDA | O26: =IF(Titanic[[#This Row],[Sexo]]="Hombre", "HOMBRE", "MUJER") -> HOMBRE | P26: =IF(Titanic[[#This Row],[Edad]]="", "", IF(Titanic[[#This Row],[Edad]]>=100, Titanic[[#This Row],[Edad]] / 10, Titanic[[#This Row],[Edad]])) -> 35 | Q26: =IFERROR(LOOKUP(Titanic[[#This Row],[Edad Corrigida]],'Práctica 1'!$K$231:$K$240,'Práctica 1'!$L$231:$L$240), "DESCONOCIDO") -> 6. ADULTO 1 | R26: =Titanic[[#This Row],[Familia Horizontal]]+Titanic[[#This Row],[Familia Vertical]] -> 0
B27: 22 | C27: 1 | D27: 2 | E27: Beesley, Mr. Lawrence | F27: Hombre | G27: 34 | H27: 0 | I27: 0 | J27: 13 | K27: 1 | L27: Southampton | M27: =IF(Titanic[[#This Row],[Sobrevive]]=1, "SOBREVIVE", "NO SOBREVIVE") -> SOBREVIVE | N27: =LOOKUP(Titanic[[#This Row],[Clase]],{1,2,3}, {"PRIMERA","SEGUNDA","TERCERA"}) -> SEGUNDA | O27: =IF(Titanic[[#This Row],[Sexo]]="Hombre", "HOMBRE", "MUJER") -> HOMBRE | P27: =IF(Titanic[[#This Row],[Edad]]="", "", IF(Titanic[[#This Row],[Edad]]>=100, Titanic[[#This Row],[Edad]] / 10, Titanic[[#This Row],[Edad]])) -> 34 | Q27: =IFERROR(LOOKUP(Titanic[[#This Row],[Edad Corrigida]],'Práctica 1'!$K$231:$K$240,'Práctica 1'!$L$231:$L$240), "DESCONOCIDO") -> 6. ADULTO 1 | R27: =Titanic[[#This Row],[Familia Horizontal]]+Titanic[[#This Row],[Familia Vertical]] -> 0
B28: 23 | C28: 1 | D28: 3 | E28: McGowan, Miss. Anna "Annie" | F28: Mujer | G28: 15 | H28: 0 | I28: 0 | J28: 80292 | K28: 0 | L28: Queenstown | M28: =IF(Titanic[[#This Row],[Sobrevive]]=1, "SOBREVIVE", "NO SOBREVIVE") -> SOBREVIVE | N28: =LOOKUP(Titanic[[#This Row],[Clase]],{1,2,3}, {"PRIMERA","SEGUNDA","TERCERA"}) -> TERCERA | O28: =IF(Titanic[[#This Row],[Sexo]]="Hombre", "HOMBRE", "MUJER") -> MUJER | P28: =IF(Titanic[[#This Row],[Edad]]="", "", IF(Titanic[[#This Row],[Edad]]>=100, Titanic[[#This Row],[Edad]] / 10, Titanic[[#This Row],[Edad]])) -> 15 | Q28: =IFERROR(LOOKUP(Titanic[[#This Row],[Edad Corrigida]],'Práctica 1'!$K$231:$K$240,'Práctica 1'!$L$231:$L$240), "DESCONOCIDO") -> 1. INFANTE | R28: =Titanic[[#This Row],[Familia Horizontal]]+Titanic[[#This Row],[Familia Vertical]] -> 0
B29: 24 | C29: 1 | D29: 1 | E29: Sloper, Mr. William Thompson | F29: Hombre | G29: 28 | H29: 0 | I29: 0 | J29: 355 | K29: 1 | L29: Southampton | M29: =IF(Titanic[[#This Row],[Sobrevive]]=1, "SOBREVIVE", "NO SOBREVIVE") -> SOBREVIVE | N29: =LOOKUP(Titanic[[#This Row],[Clase]],{1,2,3}, {"PRIMERA","SEGUNDA","TERCERA"}) -> PRIMERA | O29: =IF(Titanic[[#This Row],[Sexo]]="Hombre", "HOMBRE", "MUJER") -> HOMBRE | P29: =IF(Titanic[[#This Row],[Edad]]="", "", IF(Titanic[[#This Row],[Edad]]>=100, Titanic[[#This Row],[Edad]] / 10, Titanic[[#This Row],[Edad]])) -> 28 | Q29: =IFERROR(LOOKUP(Titanic[[#This Row],[Edad Corrigida]],'Práctica 1'!$K$231:$K$240,'Práctica 1'!$L$231:$L$240), "DESCONOCIDO") -> 4. ADULTO JOVEN | R29: =Titanic[[#This Row],[Familia Horizontal]]+Titanic[[#This Row],[Familia Vertical]] -> 0
B30: 25 | C30: 0 | D30: 3 | E30: Palsson, Miss. Torborg Danira | F30: Mujer | G30: 8 | H30: 3 | I30: 1 | J30: 21075 | K30: 0 | L30: Southampton | M30: =IF(Titanic[[#This Row],[Sobrevive]]=1, "SOBREVIVE", "NO SOBREVIVE") -> NO SOBREVIVE | N30: =LOOKUP(Titanic[[#This Row],[Clase]],{1,2,3}, {"PRIMERA","SEGUNDA","TERCERA"}) -> TERCERA | O30: =IF(Titanic[[#This Row],[Sexo]]="Hombre", "HOMBRE", "MUJER") -> MUJER | P30: =IF(Titanic[[#This Row],[Edad]]="", "", IF(Titanic[[#This Row],[Edad]]>=100, Titanic[[#This Row],[Edad]] / 10, Titanic[[#This Row],[Edad]])) -> 8 | Q30: =IFERROR(LOOKUP(Titanic[[#This Row],[Edad Corrigida]],'Práctica 1'!$K$231:$K$240,'Práctica 1'!$L$231:$L$240), "DESCONOCIDO") -> DESCONOCIDO | R30: =Titanic[[#This Row],[Familia Horizontal]]+Titanic[[#This Row],[Familia Vertical]] -> 4
B31: 26 | C31: 1 | D31: 3 | E31: Asplund, Mrs. Carl Oscar (Selma Augusta Emilia Johansson) | F31: Mujer | G31: 38 | H31: 1 | I31: 5 | J31: 313875 | K31: 0 | L31: Southampton | M31: =IF(Titanic[[#This Row],[Sobrevive]]=1, "SOBREVIVE", "NO SOBREVIVE") -> SOBREVIVE | N31: =LOOKUP(Titanic[[#This Row],[Clase]],{1,2,3}, {"PRIMERA","SEGUNDA","TERCERA"}) -> TERCERA | O31: =IF(Titanic[[#This Row],[Sexo]]="Hombre", "HOMBRE", "MUJER") -> MUJER | P31: =IF(Titanic[[#This Row],[Edad]]="", "", IF(Titanic[[#This Row],[Edad]]>=100, Titanic[[#This Row],[Edad]] / 10, Titanic[[#This Row],[Edad]])) -> 38 | Q31: =IFERROR(LOOKUP(Titanic[[#This Row],[Edad Corrigida]],'Práctica 1'!$K$231:$K$240,'Práctica 1'!$L$231:$L$240), "DESCONOCIDO") -> 7. ADULTO 2 | R31: =Titanic[[#This Row],[Familia Horizontal]]+Titanic[[#This Row],[Familia Vertical]] -> 6
B32: 27 | C32: 0 | D32: 3 | E32: Emir, Mr. Farred Chehab | F32: Hombre | H32: 0 | I32: 0 | J32: 7225 | K32: 0 | L32: Cherburg | M32: =IF(Titanic[[#This Row],[Sobrevive]]=1, "SOBREVIVE", "NO SOBREVIVE") -> NO SOBREVIVE | N32: =LOOKUP(Titanic[[#This Row],[Clase]],{1,2,3}, {"PRIMERA","SEGUNDA","TERCERA"}) -> TERCERA | O32: =IF(Titanic[[#This Row],[Sexo]]="Hombre", "HOMBRE", "MUJER") -> HOMBRE | P32: =IF(Titanic[[#This Row],[Edad]]="", "", IF(Titanic[[#This Row],[Edad]]>=100, Titanic[[#This Row],[Edad]] / 10, Titanic[[#This Row],[Edad]])) | Q32: =IFERROR(LOOKUP(Titanic[[#This Row],[Edad Corrigida]],'Práctica 1'!$K$231:$K$240,'Práctica 1'!$L$231:$L$240), "DESCONOCIDO") -> DESCONOCIDO | R32: =Titanic[[#This Row],[Familia Horizontal]]+Titanic[[#This Row],[Familia Vertical]] -> 0
B33: 28 | C33: 0 | D33: 1 | E33: Fortune, Mr. Charles Alexander | F33: Hombre | G33: 19 | H33: 3 | I33: 2 | J33: 263 | K33: 1 | L33: Southampton | M33: =IF(Titanic[[#This Row],[Sobrevive]]=1, "SOBREVIVE", "NO SOBREVIVE") -> NO SOBREVIVE | N33: =LOOKUP(Titanic[[#This Row],[Clase]],{1,2,3}, {"PRIMERA","SEGUNDA","TERCERA"}) -> PRIMERA | O33: =IF(Titanic[[#This Row],[Sexo]]="Hombre", "HOMBRE", "MUJER") -> HOMBRE | P33: =IF(Titanic[[#This Row],[Edad]]="", "", IF(Titanic[[#This Row],[Edad]]>=100, Titanic[[#This Row],[Edad]] / 10, Titanic[[#This Row],[Edad]])) -> 19 | Q33: =IFERROR(LOOKUP(Titanic[[#This Row],[Edad Corrigida]],'Práctica 1'!$K$231:$K$240,'Práctica 1'!$L$231:$L$240), "DESCONOCIDO") -> 2. ADOLESCENTE | R33: =Titanic[[#This Row],[Familia Horizontal]]+Titanic[[#This Row],[Familia Vertical]] -> 5
B34: 29 | C34: 1 | D34: 3 | E34: O'Dwyer, Miss. Ellen "Nellie" | F34: Mujer | H34: 0 | I34: 0 | J34: 78792 | K34: 0 | L34: Queenstown | M34: =IF(Titanic[[#This Row],[Sobrevive]]=1, "SOBREVIVE", "NO SOBREVIVE") -> SOBREVIVE | N34: =LOOKUP(Titanic[[#This Row],[Clase]],{1,2,3}, {"PRIMERA","SEGUNDA","TERCERA"}) -> TERCERA | O34: =IF(Titanic[[#This Row],[Sexo]]="Hombre", "HOMBRE", "MUJER") -> MUJER | P34: =IF(Titanic[[#This Row],[Edad]]="", "", IF(Titanic[[#This Row],[Edad]]>=100, Titanic[[#This Row],[Edad]] / 10, Titanic[[#This Row],[Edad]])) | Q34: =IFERROR(LOOKUP(Titanic[[#This Row],[Edad Corrigida]],'Práctica 1'!$K$231:$K$240,'Práctica 1'!$L$231:$L$240), "DESCONOCIDO") -> DESCONOCIDO | R34: =Titanic[[#This Row],[Familia Horizontal]]+Titanic[[#This Row],[Familia Vertical]] -> 0
B35: 30 | C35: 0 | D35: 3 | E35: Todoroff, Mr. Lalio | F35: Hombre | H35: 0 | I35: 0 | J35: 78958 | K35: 0 | L35: Southampton | M35: =IF(Titanic[[#This Row],[Sobrevive]]=1, "SOBREVIVE", "NO SOBREVIVE") -> NO SOBREVIVE | N35: =LOOKUP(Titanic[[#This Row],[Clase]],{1,2,3}, {"PRIMERA","SEGUNDA","TERCERA"}) -> TERCERA | O35: =IF(Titanic[[#This Row],[Sexo]]="Hombre", "HOMBRE", "MUJER") -> HOMBRE | P35: =IF(Titanic[[#This Row],[Edad]]="", "", IF(Titanic[[#This Row],[Edad]]>=100, Titanic[[#This Row],[Edad]] / 10, Titanic[[#This Row],[Edad]])) | Q35: =IFERROR(LOOKUP(Titanic[[#This Row],[Edad Corrigida]],'Práctica 1'!$K$231:$K$240,'Práctica 1'!$L$231:$L$240), "DESCONOCIDO") -> DESCONOCIDO | R35: =Titanic[[#This Row],[Familia Horizontal]]+Titanic[[#This Row],[Familia Vertical]] -> 0
B36: 31 | C36: 0 | D36: 1 | E36: Uruchurtu, Don. Manuel E | F36: Hombre | G36: 40 | H36: 0 | I36: 0 | J36: 277208 | K36: 0 | L36: Cherburg | M36: =IF(Titanic[[#This Row],[Sobrevive]]=1, "SOBREVIVE", "NO SOBREVIVE") -> NO SOBREVIVE | N36: =LOOKUP(Titanic[[#This Row],[Clase]],{1,2,3}, {"PRIMERA","SEGUNDA","TERCERA"}) -> PRIMERA | O36: =IF(Titanic[[#This Row],[Sexo]]="Hombre", "HOMBRE", "MUJER") -> HOMBRE | P36: =IF(Titanic[[#This Row],[Edad]]="", "", IF(Titanic[[#This Row],[Edad]]>=100, Titanic[[#This Row],[Edad]] / 10, Titanic[[#This Row],[Edad]])) -> 40 | Q36: =IFERROR(LOOKUP(Titanic[[#This Row],[Edad Corrigida]],'Práctica 1'!$K$231:$K$240,'Práctica 1'!$L$231:$L$240), "DESCONOCIDO") -> 7. ADULTO 2 | R36: =Titanic[[#This Row],[Familia Horizontal]]+Titanic[[#This Row],[Familia Vertical]] -> 0
B37: 32 | C37: 1 | D37: 1 | E37: Spencer, Mrs. William Augustus (Marie Eugenie) | F37: Mujer | H37: 1 | I37: 0 | J37: 1465208 | K37: 1 | L37: Cherburg | M37: =IF(Titanic[[#This Row],[Sobrevive]]=1, "SOBREVIVE", "NO SOBREVIVE") -> SOBREVIVE | N37: =LOOKUP(Titanic[[#This Row],[Clase]],{1,2,3}, {"PRIMERA","SEGUNDA","TERCERA"}) -> PRIMERA | O37: =IF(Titanic[[#This Row],[Sexo]]="Hombre", "HOMBRE", "MUJER") -> MUJER | P37: =IF(Titanic[[#This Row],[Edad]]="", "", IF(Titanic[[#This Row],[Edad]]>=100, Titanic[[#This Row],[Edad]] / 10, Titanic[[#This Row],[Edad]])) | Q37: =IFERROR(LOOKUP(Titanic[[#This Row],[Edad Corrigida]],'Práctica 1'!$K$231:$K$240,'Práctica 1'!$L$231:$L$240), "DESCONOCIDO") -> DESCONOCIDO | R37: =Titanic[[#This Row],[Familia Horizontal]]+Titanic[[#This Row],[Familia Vertical]] -> 1
B38: 33 | C38: 1 | D38: 3 | E38: Glynn, Miss. Mary Agatha | F38: Mujer | H38: 0 | I38: 0 | J38: 775 | K38: 0 | L38: Queenstown | M38: =IF(Titanic[[#This Row],[Sobrevive]]=1, "SOBREVIVE", "NO SOBREVIVE") -> SOBREVIVE | N38: =LOOKUP(Titanic[[#This Row],[Clase]],{1,2,3}, {"PRIMERA","SEGUNDA","TERCERA"}) -> TERCERA | O38: =IF(Titanic[[#This Row],[Sexo]]="Hombre", "HOMBRE", "MUJER") -> MUJER | P38: =IF(Titanic[[#This Row],[Edad]]="", "", IF(Titanic[[#This Row],[Edad]]>=100, Titanic[[#This Row],[Edad]] / 10, Titanic[[#This Row],[Edad]])) | Q38: =IFERROR(LOOKUP(Titanic[[#This Row],[Edad Corrigida]],'Práctica 1'!$K$231:$K$240,'Práctica 1'!$L$231:$L$240), "DESCONOCIDO") -> DESCONOCIDO | R38: =Titanic[[#This Row],[Familia Horizontal]]+Titanic[[#This Row],[Familia Vertical]] -> 0
B39: 34 | C39: 0 | D39: 2 | E39: Wheadon, Mr. Edward H | F39: Hombre | G39: 66 | H39: 0 | I39: 0 | J39: 105 | K39: 0 | L39: Southampton | M39: =IF(Titanic[[#This Row],[Sobrevive]]=1, "SOBREVIVE", "NO SOBREVIVE") -> NO SOBREVIVE | N39: =LOOKUP(Titanic[[#This Row],[Clase]],{1,2,3}, {"PRIMERA","SEGUNDA","TERCERA"}) -> SEGUNDA | O39: =IF(Titanic[[#This Row],[Sexo]]="Hombre", "HOMBRE", "MUJER") -> HOMBRE | P39: =IF(Titanic[[#This Row],[Edad]]="", "", IF(Titanic[[#This Row],[Edad]]>=100, Titanic[[#This Row],[Edad]] / 10, Titanic[[#This Row],[Edad]])) -> 66 | Q39: =IFERROR(LOOKUP(Titanic[[#This Row],[Edad Corrigida]],'Práctica 1'!$K$231:$K$240,'Práctica 1'!$L$231:$L$240), "DESCONOCIDO") -> 9. ADULTO 4 | R39: =Titanic[[#This Row],[Familia Horizontal]]+Titanic[[#This Row],[Familia Vertical]] -> 0
B40: 35 | C40: 0 | D40: 1 | E40: Meyer, Mr. Edgar Joseph | F40: Hombre | G40: 28 | H40: 1 | I40: 0 | J40: 821708 | K40: 0 | L40: Cherburg | M40: =IF(Titanic[[#This Row],[Sobrevive]]=1, "SOBREVIVE", "NO SOBREVIVE") -> NO SOBREVIVE | N40: =LOOKUP(Titanic[[#This Row],[Clase]],{1,2,3}, {"PRIMERA","SEGUNDA","TERCERA"}) -> PRIMERA | O40: =IF(Titanic[[#This Row],[Sexo]]="Hombre", "HOMBRE", "MUJER") -> HOMBRE | P40: =IF(Titanic[[#This Row],[Edad]]="", "", IF(Titanic[[#This Row],[Edad]]>=100, Titanic[[#This Row],[Edad]] / 10, Titanic[[#This Row],[Edad]])) -> 28 | Q40: =IFERROR(LOOKUP(Titanic[[#This Row],[Edad Corrigida]],'Práctica 1'!$K$231:$K$240,'Práctica 1'!$L$231:$L$240), "DESCONOCIDO") -> 4. ADULTO JOVEN | R40: =Titanic[[#This Row],[Familia Horizontal]]+Titanic[[#This Row],[Familia Vertical]] -> 1
B41: 36 | C41: 0 | D41: 1 | E41: Holverson, Mr. Alexander Oskar | F41: Hombre | G41: 42 | H41: 1 | I41: 0 | J41: 52 | K41: 0 | L41: Southampton | M41: =IF(Titanic[[#This Row],[Sobrevive]]=1, "SOBREVIVE", "NO SOBREVIVE") -> NO SOBREVIVE | N41: =LOOKUP(Titanic[[#This Row],[Clase]],{1,2,3}, {"PRIMERA","SEGUNDA","TERCERA"}) -> PRIMERA | O41: =IF(Titanic[[#This Row],[Sexo]]="Hombre", "HOMBRE", "MUJER") -> HOMBRE | P41: =IF(Titanic[[#This Row],[Edad]]="", "", IF(Titanic[[#This Row],[Edad]]>=100, Titanic[[#This Row],[Edad]] / 10, Titanic[[#This Row],[Edad]])) -> 42 | Q41: =IFERROR(LOOKUP(Titanic[[#This Row],[Edad Corrigida]],'Práctica 1'!$K$231:$K$240,'Práctica 1'!$L$231:$L$240), "DESCONOCIDO") -> 8. ADULTO 3 | R41: =Titanic[[#This Row],[Familia Horizontal]]+Titanic[[#This Row],[Familia Vertical]] -> 1
B42: 37 | C42: 1 | D42: 3 | E42: Mamee, Mr. Hanna | F42: Hombre | H42: 0 | I42: 0 | J42: 72292 | K42: 0 | L42: Cherburg | M42: =IF(Titanic[[#This Row],[Sobrevive]]=1, "SOBREVIVE", "NO SOBREVIVE") -> SOBREVIVE | N42: =LOOKUP(Titanic[[#This Row],[Clase]],{1,2,3}, {"PRIMERA","SEGUNDA","TERCERA"}) -> TERCERA | O42: =IF(Titanic[[#This Row],[Sexo]]="Hombre", "HOMBRE", "MUJER") -> HOMBRE | P42: =IF(Titanic[[#This Row],[Edad]]="", "", IF(Titanic[[#This Row],[Edad]]>=100, Titanic[[#This Row],[Edad]] / 10, Titanic[[#This Row],[Edad]])) | Q42: =IFERROR(LOOKUP(Titanic[[#This Row],[Edad Corrigida]],'Práctica 1'!$K$231:$K$240,'Práctica 1'!$L$231:$L$240), "DESCONOCIDO") -> DESCONOCIDO | R42: =Titanic[[#This Row],[Familia Horizontal]]+Titanic[[#This Row],[Familia Vertical]] -> 0
B43: 38 | C43: 0 | D43: 3 | E43: Cann, Mr. Ernest Charles | F43: Hombre | G43: 21 | H43: 0 | I43: 0 | J43: 805 | K43: 0 | L43: Southampton | M43: =IF(Titanic[[#This Row],[Sobrevive]]=1, "SOBREVIVE", "NO SOBREVIVE") -> NO SOBREVIVE | N43: =LOOKUP(Titanic[[#This Row],[Clase]],{1,2,3}, {"PRIMERA","SEGUNDA","TERCERA"}) -> TERCERA | O43: =IF(Titanic[[#This Row],[Sexo]]="Hombre", "HOMBRE", "MUJER") -> HOMBRE | P43: =IF(Titanic[[#This Row],[Edad]]="", "", IF(Titanic[[#This Row],[Edad]]>=100, Titanic[[#This Row],[Edad]] / 10, Titanic[[#This Row],[Edad]])) -> 21 | Q43: =IFERROR(LOOKUP(Titanic[[#This Row],[Edad Corrigida]],'Práctica 1'!$K$231:$K$240,'Práctica 1'!$L$231:$L$240), "DESCONOCIDO") -> 2. ADOLESCENTE | R43: =Titanic[[#This Row],[Familia Horizontal]]+Titanic[[#This Row],[Familia Vertical]] -> 0
...

Sheet Análisis de Edades por Deciles
B3: Cuenta de C Sobrevive | C3: Etiquetas de columna
B4: Etiquetas de fila | C4: NO SOBREVIVE | D4: SOBREVIVE | E4: Total general
B5: 1. INFANTE | C5: 1 | D5: 10 | E5: 11
B6: 2. ADOLESCENTE | C6: 3 | D6: 5 | E6: 8
B7: 3. JOVEN | C7: 3 | D7: 12 | E7: 15
B8: 4. ADULTO JOVEN | C8: 4 | D8: 9 | E8: 13
B9: 5. ADULTO | C9: 5 | D9: 9 | E9: 14
B10: 6. ADULTO 1 | C10: 1 | D10: 15 | E10: 16
B11: 7. ADULTO 2 | C11: 9 | D11: 20 | E11: 29
B12: 8. ADULTO 3 | C12: 13 | D12: 18 | E12: 31
B13: 9. ADULTO 4 | C13: 24 | D13: 20 | E13: 44
B14: A. ADULTO MAYOR | D14: 1 | E14: 1
B15: Total general | C15: 63 | D15: 119 | E15: 182
M33: Informe
M35: Para hombres
M37: La supervivencia aumenta ligeramente cuando la edad pertence a Adulto 1 (cerca de los 32 años) y Adulto 3 (cerca de los 42 años)
M40: Para mujeres
M42: …

Sheet Hoja8
D2: Cortes de Familiares | G2: Cortes de Pagado
B3: 0.2 | D3: =_xlfn.PERCENTILE.INC(Titanic[Familiares], B3) -> 0 | E3: SOLO | G3: =_xlfn.PERCENTILE.INC(Titanic[Pagado], B3) -> 105 | H3: PAGO BÁSICO
B4: 0.4 | D4: =_xlfn.PERCENTILE.INC(Titanic[Familiares], B4) -> 0 | G4: =_xlfn.PERCENTILE.INC(Titanic[Pagado], B4) -> 775 | H4: PAGO NORMAL
B5: 0.6 | D5: =_xlfn.PERCENTILE.INC(Titanic[Familiares], B5) -> 0 | G5: =_xlfn.PERCENTILE.INC(Titanic[Pagado], B5) -> 7925 | H5: PAGO LUJO
B6: 0.8 | D6: =_xlfn.PERCENTILE.INC(Titanic[Familiares], B6) -> 2 | E6: FAMILIA NORMAL | G6: =_xlfn.PERCENTILE.INC(Titanic[Pagado], B6) -> 86625 | H6: PAGO SÚPER LUJO
B7: 1 | D7: =_xlfn.PERCENTILE.INC(Titanic[Familiares], B7) -> 10 | E7: FAMILIA GRANDE | G7: =_xlfn.PERCENTILE.INC(Titanic[Pagado], B7) -> 5123292 | H7: MILLONARIO
D10: 0 | E10: SOLO
D11: 2 | E11: FAMILIA NORMAL
D12: 10 | E12: FAMILIA GRANDE

Sheet Hoja3
C2: EJE PERCENTIL
B4: {=Titanic[Edad Corrigida]} -> 22 | C4: =IFERROR(_xlfn.PERCENTRANK.INC(Titanic[Edad Corrigida], B4), "") -> 0.276 | E4: {=_xlfn._xlws.SORT(_xlfn.UNIQUE(Titanic[Edad Corrigida]))} -> 1 | F4: =IFERROR(ROUNDUP(E4/5, 0), "DESCONOCIDO") -> 1
B5: 38 | C5: =IFERROR(_xlfn.PERCENTRANK.INC(Titanic[Edad Corrigida], B5), "") -> 0.727 | E5: 2 | F5: =IFERROR(ROUNDUP(E5/5, 0), "DESCONOCIDO") -> 1
B6: 26 | C6: =IFERROR(_xlfn.PERCENTRANK.INC(Titanic[Edad Corrigida], B6), "") -> 0.412 | E6: 3 | F6: =IFERROR(ROUNDUP(E6/5, 0), "DESCONOCIDO") -> 1
B7: 35 | C7: =IFERROR(_xlfn.PERCENTRANK.INC(Titanic[Edad Corrigida], B7), "") -> 0.661 | E7: 4 | F7: =IFERROR(ROUNDUP(E7/5, 0), "DESCONOCIDO") -> 1
B8: 35 | C8: =IFERROR(_xlfn.PERCENTRANK.INC(Titanic[Edad Corrigida], B8), "") -> 0.661 | E8: 5 | F8: =IFERROR(ROUNDUP(E8/5, 0), "DESCONOCIDO") -> 1
C9: =IFERROR(_xlfn.PERCENTRANK.INC(Titanic[Edad Corrigida], B9), "") | E9: 6 | F9: =IFERROR(ROUNDUP(E9/5, 0), "DESCONOCIDO") -> 2
B10: 54 | C10: =IFERROR(_xlfn.PERCENTRANK.INC(Titanic[Edad Corrigida], B10), "") -> 0.922 | E10: 7 | F10: =IFERROR(ROUNDUP(E10/5, 0), "DESCONOCIDO") -> 2
B11: 2 | C11: =IFERROR(_xlfn.PERCENTRANK.INC(Titanic[Edad Corrigida], B11), "") -> 0.009 | E11: 8 | F11: =IFERROR(ROUNDUP(E11/5, 0), "DESCONOCIDO") -> 2
B12: 27 | C12: =IFERROR(_xlfn.PERCENTRANK.INC(Titanic[Edad Corrigida], B12), "") -> 0.437 | E12: 9 | F12: =IFERROR(ROUNDUP(E12/5, 0), "DESCONOCIDO") -> 2
B13: 14 | C13: =IFERROR(_xlfn.PERCENTRANK.INC(Titanic[Edad Corrigida], B13), "") -> 0.089 | E13: 10 | F13: =IFERROR(ROUNDUP(E13/5, 0), "DESCONOCIDO") -> 2
B14: 4 | C14: =IFERROR(_xlfn.PERCENTRANK.INC(Titanic[Edad Corrigida], B14), "") -> 0.032 | E14: 11 | F14: =IFERROR(ROUNDUP(E14/5, 0), "DESCONOCIDO") -> 3
B15: 58 | C15: =IFERROR(_xlfn.PERCENTRANK.INC(Titanic[Edad Corrigida], B15), "") -> 0.946 | E15: 12 | F15: =IFERROR(ROUNDUP(E15/5, 0), "DESCONOCIDO") -> 3
B16: 20 | C16: =IFERROR(_xlfn.PERCENTRANK.INC(Titanic[Edad Corrigida], B16), "") -> 0.22 | E16: 13 | F16: =IFERROR(ROUNDUP(E16/5, 0), "DESCONOCIDO") -> 3
B17: 39 | C17: =IFERROR(_xlfn.PERCENTRANK.INC(Titanic[Edad Corrigida], B17), "") -> 0.743 | E17: 14 | F17: =IFERROR(ROUNDUP(E17/5, 0), "DESCONOCIDO") -> 3
B18: 14 | C18: =IFERROR(_xlfn.PERCENTRANK.INC(Titanic[Edad Corrigida], B18), "") -> 0.089 | E18: 14.5 | F18: =IFERROR(ROUNDUP(E18/5, 0), "DESCONOCIDO") -> 3
B19: 55 | C19: =IFERROR(_xlfn.PERCENTRANK.INC(Titanic[Edad Corrigida], B19), "") -> 0.934 | E19: 15 | F19: =IFERROR(ROUNDUP(E19/5, 0), "DESCONOCIDO") -> 3
B20: 2 | C20: =IFERROR(_xlfn.PERCENTRANK.INC(Titanic[Edad Corrigida], B20), "") -> 0.009 | E20: 16 | F20: =IFERROR(ROUNDUP(E20/5, 0), "DESCONOCIDO") -> 4
C21: =IFERROR(_xlfn.PERCENTRANK.INC(Titanic[Edad Corrigida], B21), "") | E21: 17 | F21: =IFERROR(ROUNDUP(E21/5, 0), "DESCONOCIDO") -> 4
B22: 31 | C22: =IFERROR(_xlfn.PERCENTRANK.INC(Titanic[Edad Corrigida], B22), "") -> 0.566 | E22: 18 | F22: =IFERROR(ROUNDUP(E22/5, 0), "DESCONOCIDO") -> 4
C23: =IFERROR(_xlfn.PERCENTRANK.INC(Titanic[Edad Corrigida], B23), "") | E23: 19 | F23: =IFERROR(ROUNDUP(E23/5, 0), "DESCONOCIDO") -> 4
B24: 35 | C24: =IFERROR(_xlfn.PERCENTRANK.INC(Titanic[Edad Corrigida], B24), "") -> 0.661 | E24: 20 | F24: =IFERROR(ROUNDUP(E24/5, 0), "DESCONOCIDO") -> 4
B25: 34 | C25: =IFERROR(_xlfn.PERCENTRANK.INC(Titanic[Edad Corrigida], B25), "") -> 0.639 | E25: 20.5 | F25: =IFERROR(ROUNDUP(E25/5, 0), "DESCONOCIDO") -> 5
B26: 15 | C26: =IFERROR(_xlfn.PERCENTRANK.INC(Titanic[Edad Corrigida], B26), "") -> 0.099 | E26: 21 | F26: =IFERROR(ROUNDUP(E26/5, 0), "DESCONOCIDO") -> 5
B27: 28 | C27: =IFERROR(_xlfn.PERCENTRANK.INC(Titanic[Edad Corrigida], B27), "") -> 0.462 | E27: 22 | F27: =IFERROR(ROUNDUP(E27/5, 0), "DESCONOCIDO") -> 5
B28: 8 | C28: =IFERROR(_xlfn.PERCENTRANK.INC(Titanic[Edad Corrigida], B28), "") -> 0.06 | E28: 23 | F28: =IFERROR(ROUNDUP(E28/5, 0), "DESCONOCIDO") -> 5
B29: 38 | C29: =IFERROR(_xlfn.PERCENTRANK.INC(Titanic[Edad Corrigida], B29), "") -> 0.727 | E29: 23.5 | F29: =IFERROR(ROUNDUP(E29/5, 0), "DESCONOCIDO") -> 5
C30: =IFERROR(_xlfn.PERCENTRANK.INC(Titanic[Edad Corrigida], B30), "") | E30: 24 | F30: =IFERROR(ROUNDUP(E30/5, 0), "DESCONOCIDO") -> 5
B31: 19 | C31: =IFERROR(_xlfn.PERCENTRANK.INC(Titanic[Edad Corrigida], B31), "") -> 0.185 | E31: 24.5 | F31: =IFERROR(ROUNDUP(E31/5, 0), "DESCONOCIDO") -> 5
C32: =IFERROR(_xlfn.PERCENTRANK.INC(Titanic[Edad Corrigida], B32), "") | E32: 25 | F32: =IFERROR(ROUNDUP(E32/5, 0), "DESCONOCIDO") -> 5
C33: =IFERROR(_xlfn.PERCENTRANK.INC(Titanic[Edad Corrigida], B33), "") | E33: 26 | F33: =IFERROR(ROUNDUP(E33/5, 0), "DESCONOCIDO") -> 6
B34: 40 | C34: =IFERROR(_xlfn.PERCENTRANK.INC(Titanic[Edad Corrigida], B34), "") -> 0.762 | E34: 27 | F34: =IFERROR(ROUNDUP(E34/5, 0), "DESCONOCIDO") -> 6
C35: =IFERROR(_xlfn.PERCENTRANK.INC(Titanic[Edad Corrigida], B35), "") | E35: 28 | F35: =IFERROR(ROUNDUP(E35/5, 0), "DESCONOCIDO") -> 6
C36: =IFERROR(_xlfn.PERCENTRANK.INC(Titanic[Edad Corrigida], B36), "") | E36: 28.5 | F36: =IFERROR(ROUNDUP(E36/5, 0), "DESCONOCIDO") -> 6
B37: 66 | C37: =IFERROR(_xlfn.PERCENTRANK.INC(Titanic[Edad Corrigida], B37), "") -> 0.981 | E37: 29 | F37: =IFERROR(ROUNDUP(E37/5, 0), "DESCONOCIDO") -> 6
B38: 28 | C38: =IFERROR(_xlfn.PERCENTRANK.INC(Titanic[Edad Corrigida], B38), "") -> 0.462 | E38: 30 | F38: =IFERROR(ROUNDUP(E38/5, 0), "DESCONOCIDO") -> 6
B39: 42 | C39: =IFERROR(_xlfn.PERCENTRANK.INC(Titanic[Edad Corrigida], B39), "") -> 0.792 | E39: 30.5 | F39: =IFERROR(ROUNDUP(E39/5, 0), "DESCONOCIDO") -> 7
C40: =IFERROR(_xlfn.PERCENTRANK.INC(Titanic[Edad Corrigida], B40), "") | E40: 31 | F40: =IFERROR(ROUNDUP(E40/5, 0), "DESCONOCIDO") -> 7
B41: 21 | C41: =IFERROR(_xlfn.PERCENTRANK.INC(Titanic[Edad Corrigida], B41), "") -> 0.242 | E41: 32 | F41: =IFERROR(ROUNDUP(E41/5, 0), "DESCONOCIDO") -> 7
B42: 18 | C42: =IFERROR(_xlfn.PERCENTRANK.INC(Titanic[Edad Corrigida], B42), "") -> 0.148 | E42: 32.5 | F42: =IFERROR(ROUNDUP(E42/5, 0), "DESCONOCIDO") -> 7
...

Sheet Práctica 1
E6: PERCENTIL
C7: I | D7: X | E7: A
C8: 6
C9: 18
C10: 20
C11: 27
C12: 29
C13: 30
C14: 32
C15: 33
C16: 37
C17: 43
C18: 46
C19: 47
... C184: 889
C185: 165 | D185: 1 | E185: 0
C186: 173 | D186: 1 | E186: 0
C187: 184 | D187: 1 | E187: 0
C188: 382 | D188: 1 | E188: 0
C189: 387 | D189: 1 | E189: 0
C190: 789 | D190: 1 | E190: 0
C191: 828 | D191: 1 | E191: 0 | H191: =COUNTA(D185:D191) -> 7 | I191: 891 | J191: =H191/I191 -> 0.0078563412
C192: 8 | D192: 2 | E192: 0.009
C193: 17 | D193: 2 | E193: 0.009
C194: 120 | D194: 2 | E194: 0.009
C195: 206 | D195: 2 | E195: 0.009
C196: 298 | D196: 2 | E196: 0.009
C197: 341 | D197: 2 | E197: 0.009
C198: 480 | D198: 2 | E198: 0.009
C199: 531 | D199: 2 | E199: 0.009 | L199: {=COUNT(_xlfn._xlws.FILTER(Titanic[Edad Corrigida], Titanic[Edad Corrigida] = L200))} -> 7 | M199: {=COUNT(_xlfn._xlws.FILTER(Titanic[Edad Corrigida], Titanic[Edad Corrigida] = M200))} -> 10 | N199: {=COUNT(_xlfn._xlws.FILTER(Titanic[Edad Corrigida], Titanic[Edad Corrigida] = N200))} -> 6 | O199: {=COUNT(_xlfn._xlws.FILTER(Titanic[Edad Corrigida], Titanic[Edad Corrigida] = O200))} -> 10 | P199: {=COUNT(_xlfn._xlws.FILTER(Titanic[Edad Corrigida], Titanic[Edad Corrigida] = P200))} -> 4
C200: 643 | D200: 2 | E200: 0.009 | L200: {=TRANSPOSE(_xlfn._xlws.SORT(_xlfn.UNIQUE(Titanic[Edad Corrigida])))} -> 1 | M200: 2 | N200: 3 | O200: 4 | P200: 5 | Q200: 6 | R200: 7 | S200: 8 | T200: 9 | U200: 10 | V200: 11 | W200: 12 | X200: 13 | Y200: 14 | Z200: 14.5 | AA200: 15 | AB200: 16 | AC200: 17 | AD200: 18 | AE200: 19 | AF200: 20 | AG200: 20.5 | AH200: 21 | AI200: 22 | AJ200: 23 | AK200: 23.5 | AL200: 24 | AM200: 24.5 | AN200: 25 | AO200: 26 | AP200: 27 | AQ200: 28 | AR200: 28.5 | AS200: 29 | AT200: 30 | AU200: 30.5 | AV200: 31 | AW200: 32 | AX200: 32.5 | AY200: 33 | AZ200: 34 | BA200: 34.5 | BB200: 35 | BC200: 36 | BD200: 36.5 | BE200: 37 | BF200: 38 | BG200: 39 | BH200: 40 | BI200: 40.5 | BJ200: 41 | BK200: 42 | BL200: 43 | BM200: 44 | BN200: 45 | BO200: 45.5 | BP200: 46 | BQ200: 47 | BR200: 48 | BS200: 49 | BT200: 50 | BU200: 51 | BV200: 52 | BW200: 53 | BX200: 54 | BY200: 55 | BZ200: 55.5 | CA200: 56 | CB200: 57 | CC200: 58 | CD200: 59 | CE200: 60 | CF200: 61 | CG200: 62 | CH200: 63 | CI200: 64 | CJ200: 65 | CK200: 66 | CL200: 67 | CM200: 70 | CN200: 70.5 | CO200: 71 | CP200: 74 | CQ200: 75 | CR200: 80 | CS200: 83 | CT200: 92
C201: 825 | D201: 2 | E201: 0.009 | H201: =COUNT(D192:D201) -> 10 | I201: 891 | J201: =H201/I201 -> 0.011223345
C202: 44 | D202: 3 | E202: 0.023 | L202: {=_xlfn._xlws.FILTER(Titanic[Edad Corrigida], Titanic[Edad Corrigida] = L200)} -> 1 | M202: {=_xlfn._xlws.FILTER(Titanic[Edad Corrigida], Titanic[Edad Corrigida] = M200)} -> 2 | N202: {=_xlfn._xlws.FILTER(Titanic[Edad Corrigida], Titanic[Edad Corrigida] = N200)} -> 3 | O202: {=_xlfn._xlws.FILTER(Titanic[Edad Corrigida], Titanic[Edad Corrigida] = O200)} -> 4 | P202: {=_xlfn._xlws.FILTER(Titanic[Edad Corrigida], Titanic[Edad Corrigida] = P200)} -> 5
C203: 194 | D203: 3 | E203: 0.023 | L203: 1 | M203: 2 | N203: 3 | O203: 4 | P203: 5
C204: 262 | D204: 3 | E204: 0.023 | L204: 1 | M204: 2 | N204: 3 | O204: 4 | P204: 5
C205: 349 | D205: 3 | E205: 0.023 | L205: 1 | M205: 2 | N205: 3 | O205: 4 | P205: 5
C206: 375 | D206: 3 | E206: 0.023 | L206: 1 | M206: 2 | N206: 3 | O206: 4
C207: 408 | D207: 3 | E207: 0.023 | H207: =COUNT(D202:D207) -> 6 | I207: 891 | J207: =H207/I207 -> 0.0067340067 | L207: 1 | M207: 2 | N207: 3 | O207: 4
C208: 11 | D208: 4 | E208: 0.032 | L208: 1 | M208: 2 | O208: 4
C209: 64 | D209: 4 | E209: 0.032 | M209: 2 | O209: 4
...

Sheet Hoja6
B2: EDAD
B3: {=Titanic[Edad Corrigida]} -> 22
B4: 38
B5: 26
B6: 35
B7: 35
B9: 54
B10: 2
B11: 27
B12: 14
B13: 4
B14: 58
B15: 20
B16: 39
... B893: 32

Sheet Hoja7
B5: 22 | D5: Posición | F5: Jerarquía | G5: Porcentaje
B6: 38 | D6: 245 | E6: 92 | F6: 1 | G6: 1
B7: 26 | D7: 61 | E7: 83 | F7: 2 | G7: 0.997
B8: 35 | D8: 666 | E8: 83 | F8: 2 | G8: 0.997
B9: 35 | D9: 500 | E9: 80 | F9: 4 | G9: 0.995
B10: 54 | D10: 376 | E10: 75 | F10: 5 | G10: 0.992
B11: 2 | D11: 511 | E11: 75 | F11: 5 | G11: 0.992
B12: 27 | D12: 681 | E12: 74 | F12: 7 | G12: 0.991
B13: 14 | D13: 76 | E13: 71 | F13: 8 | G13: 0.988
B14: 4 | D14: 395 | E14: 71 | F14: 8 | G14: 0.988
B15: 58 | D15: 93 | E15: 70.5 | F15: 10 | G15: 0.987
B16: 20 | D16: 533 | E16: 70 | F16: 11 | G16: 0.984
B17: 39 | D17: 594 | E17: 70 | F17: 11 | G17: 0.984
... B718: 32 | D718: 630 | E718: 1 | F718: 708 | G718: 0
D719: 663 | E719: 1 | F719: 708 | G719: 0
D720: 1 | F720: #N/A | G720: #N/A
D721: 716 | F721: #N/A | G721: #N/A
D722: 717 | F722: #N/A | G722: #N/A
D723: 718 | F723: #N/A | G723: #N/A
D724: 719 | F724: #N/A | G724: #N/A
D725: 720 | F725: #N/A | G725: #N/A
D726: 721 | F726: #N/A | G726: #N/A
D727: 722 | F727: #N/A | G727: #N/A
D728: 723 | F728: #N/A | G728: #N/A
D729: 724 | F729: #N/A | G729: #N/A
D730: 725 | F730: #N/A | G730: #N/A
D731: 726 | F731: #N/A | G731: #N/A
... D895: 890 | F895: #N/A | G895: #N/A
